Workbook
Name Slicer_Month: #N/A
Name Slicer_Month_Year: #N/A
Name Slicer_Month_Year1: #N/A
Name Slicer_Month_Year2: #N/A
Name Slicer_Year: #N/A

Sheet Commission Calculator
A1: SALES COMMISSION CALCULATOR
A2: ="Performance window: "&D6&" | Reporting month: "&TEXT(A6,"mmm yyyy")&" | Prepared September 1, 2026" -> Performance window: Trailing 12 Months | Reporting month: Aug 2025 | Prepared September 1, 2026
A3: Illustrative comp-plan model for analysis purposes only. Rates and tier structure below are editable assumptions, not the company's actual compensation plan.
A5: REPORTING MONTH (drop down) | D5: PERFORMANCE WINDOW (drop down) | G5: ELIGIBILITY THRESHOLD | I5: ACCELERATOR BREAKPOINT
A6: 45870 | D6: Trailing 12 Months | G6: 0.5 | I6: 1.5
A8: COMP PLAN ASSUMPTIONS (EDITABLE, ILLUSTRATIVE RATES BY ROLE)
A9: ="Tier 1: on-target commission up to 100% of quota, at the Base Rate; Tier 2: bookings from 100% up to "&TEXT(I6,"0%")&" of quota, at the Accelerator Rate; Tier 3: bookings beyond "&TEXT(I6,"0%")&" of quota, at the Super-Accelerator Rate; Note: Reps below the eligibility threshold ("&TEXT($G$6,"0%")&" attainment) earn $0 commission this window." -> Tier 1: on-target commission up to 100% of quota, at the Base Rate; Tier 2: bookings from 100% up to 150% of quota, at the Accelerator Rate; Tier 3: bookings beyond 150% of quota, at the Super-Accelerator Rate; Note: Reps below the eligibility threshold (50% attainment) earn $0 commission this window.
A12: Role | B12: Base Rate (Tier 1, ≤100% quota) | C12: Accelerator Rate (Tier 2) | D12: Super-Accelerator Rate (Tier 3)
A13: SDR / Inside Sales Rep | B13: 0.03 | C13: 0.05 | D13: 0.07
A14: Mid-Market AE | B14: 0.05 | C14: 0.08 | D14: 0.11
A15: Enterprise AE | B15: 0.06 | C15: 0.1 | D15: 0.14
A16: Senior Enterprise AE | B16: 0.07 | C16: 0.11 | D16: 0.16
A18: ="COMMISSION PAYOUT SUMMARY for: " &D6&"" -> COMMISSION PAYOUT SUMMARY for: Trailing 12 Months
A20: TOTAL COMMISSION PAYOUT | D20: TOTAL BOOKINGS WON | G20: COMPANY ATTAINMENT % | J20: AVG EFFECTIVE COMMISSION RATE
A21: =SUM($N$165:$N$214) -> 582568.5 | D21: =SUM($H$165:$H$214) -> 10862900 | G21: =IFERROR(SUM($H$165:$H$214)/SUM($G$165:$G$214),"") -> 1.0285376 | J21: =IFERROR(SUM($N$165:$N$214)/SUM($H$165:$H$214),"") -> 0.053629187
A22: all eligible reps, selected window | D22: same window | G22: bookings won ÷ quota | J22: blended payout ÷ bookings won
A24: ELIGIBLE REPS | D24: REPS BELOW THRESHOLD | G24: AVG PAYOUT PER ELIGIBLE REP | J24: ACCELERATOR $ PAID (TIER 2+3)
A25: =COUNTIFS($F$165:$F$214,"Active",$J$165:$J$214,TRUE()) -> 37 | D25: =COUNTIFS($F$165:$F$214,"Active",$J$165:$J$214,FALSE()) -> 5 | G25: =IFERROR(SUM($N$165:$N$214)/COUNTIFS($F$165:$F$214,"Active",$J$165:$J$214,TRUE()),"") -> 15745.095 | J25: =SUM($L$165:$L$214)+SUM($M$165:$M$214) -> 122882.5
A26: active reps ≥ eligibility threshold | D26: active reps earning $0 commission | G26: total payout ÷ eligible headcount | J26: commission earned above Tier 1
A29: COMMISSION TREND for 24-MONTH HISTORY
A62: ="COMMISSION BY ROLE & TEAM for: " &D6&"" -> COMMISSION BY ROLE & TEAM for: Trailing 12 Months
A82: Role | B82: Eligible Reps | C82: Bookings Won | D82: Total Commission | E82: Avg Effective Rate | G82: Team | H82: Eligible Reps | I82: Bookings Won | J82: Total Commission | K82: Avg Effective Rate
A83: SDR / Inside Sales Rep | B83: =COUNTIFS($C$165:$C$214,A83,$F$165:$F$214,"Active",$J$165:$J$214,TRUE()) -> 20 | C83: =SUMIF($C$165:$C$214,A83,$H$165:$H$214) -> 3630000 | D83: =SUMIF($C$165:$C$214,A83,$N$165:$N$214) -> 112484 | E83: =IFERROR(D83/C83,"") -> 0.030987328 | G83: Inside Sales | H83: =COUNTIFS($D$165:$D$214,G83,$F$165:$F$214,"Active",$J$165:$J$214,TRUE()) -> 20 | I83: =SUMIF($D$165:$D$214,G83,$H$165:$H$214) -> 3630000 | J83: =SUMIF($D$165:$D$214,G83,$N$165:$N$214) -> 112484 | K83: =IFERROR(J83/I83,"") -> 0.030987328
A84: Mid-Market AE | B84: =COUNTIFS($C$165:$C$214,A84,$F$165:$F$214,"Active",$J$165:$J$214,TRUE()) -> 10 | C84: =SUMIF($C$165:$C$214,A84,$H$165:$H$214) -> 2656200 | D84: =SUMIF($C$165:$C$214,A84,$N$165:$N$214) -> 146810.5 | E84: =IFERROR(D84/C84,"") -> 0.055270876 | G84: Mid-Market | H84: =COUNTIFS($D$165:$D$214,G84,$F$165:$F$214,"Active",$J$165:$J$214,TRUE()) -> 10 | I84: =SUMIF($D$165:$D$214,G84,$H$165:$H$214) -> 2656200 | J84: =SUMIF($D$165:$D$214,G84,$N$165:$N$214) -> 146810.5 | K84: =IFERROR(J84/I84,"") -> 0.055270876
A85: Enterprise AE | B85: =COUNTIFS($C$165:$C$214,A85,$F$165:$F$214,"Active",$J$165:$J$214,TRUE()) -> 4 | C85: =SUMIF($C$165:$C$214,A85,$H$165:$H$214) -> 2337100 | D85: =SUMIF($C$165:$C$214,A85,$N$165:$N$214) -> 156646 | E85: =IFERROR(D85/C85,"") -> 0.067025801 | G85: Enterprise | H85: =COUNTIFS($D$165:$D$214,G85,$F$165:$F$214,"Active",$J$165:$J$214,TRUE()) -> 4 | I85: =SUMIF($D$165:$D$214,G85,$H$165:$H$214) -> 2337100 | J85: =SUMIF($D$165:$D$214,G85,$N$165:$N$214) -> 156646 | K85: =IFERROR(J85/I85,"") -> 0.067025801
A86: Senior Enterprise AE | B86: =COUNTIFS($C$165:$C$214,A86,$F$165:$F$214,"Active",$J$165:$J$214,TRUE()) -> 3 | C86: =SUMIF($C$165:$C$214,A86,$H$165:$H$214) -> 2239600 | D86: =SUMIF($C$165:$C$214,A86,$N$165:$N$214) -> 166628 | E86: =IFERROR(D86/C86,"") -> 0.074400786 | G86: Strategic | H86: =COUNTIFS($D$165:$D$214,G86,$F$165:$F$214,"Active",$J$165:$J$214,TRUE()) -> 3 | I86: =SUMIF($D$165:$D$214,G86,$H$165:$H$214) -> 2239600 | J86: =SUMIF($D$165:$D$214,G86,$N$165:$N$214) -> 166628 | K86: =IFERROR(J86/I86,"") -> 0.074400786
A89: ="PER-REP COMMISSION for: " &D6&" (RANKED BY PAYOUT)" -> PER-REP COMMISSION for: Trailing 12 Months (RANKED BY PAYOUT)
A91: Rank | B91: Rep Name | C91: Role | D91: Team | E91: Region | F91: Quota | G91: Bookings Won | H91: Attainment % | I91: Eligible? | J91: Tier 1 $ | K91: Tier 2 $ | L91: Tier 3 $ | M91: Total Commission | N91: Effective Rate %
A92: 1 | B92: =IFERROR(INDEX($B$165:$B$214,MATCH(LARGE($P$165:$P$214,1),$P$165:$P$214,0)),"") -> Fatima Rossi | C92: =IFERROR(INDEX($C$165:$C$214,MATCH(LARGE($P$165:$P$214,1),$P$165:$P$214,0)),"") -> Senior Enterprise AE | D92: =IFERROR(INDEX($D$165:$D$214,MATCH(LARGE($P$165:$P$214,1),$P$165:$P$214,0)),"") -> Strategic | E92: =IFERROR(INDEX($E$165:$E$214,MATCH(LARGE($P$165:$P$214,1),$P$165:$P$214,0)),"") -> NAMER | F92: =IFERROR(INDEX($G$165:$G$214,MATCH(LARGE($P$165:$P$214,1),$P$165:$P$214,0)),"") -> 565500 | G92: =IFERROR(INDEX($H$165:$H$214,MATCH(LARGE($P$165:$P$214,1),$P$165:$P$214,0)),"") -> 719200 | H92: =IFERROR(INDEX($I$165:$I$214,MATCH(LARGE($P$165:$P$214,1),$P$165:$P$214,0)),"") -> 1.2717949 | I92: =IFERROR(INDEX($J$165:$J$214,MATCH(LARGE($P$165:$P$214,1),$P$165:$P$214,0)),"") -> TRUE | J92: =IFERROR(INDEX($K$165:$K$214,MATCH(LARGE($P$165:$P$214,1),$P$165:$P$214,0)),"") -> 39585 | K92: =IFERROR(INDEX($L$165:$L$214,MATCH(LARGE($P$165:$P$214,1),$P$165:$P$214,0)),"") -> 16907 | L92: =IFERROR(INDEX($M$165:$M$214,MATCH(LARGE($P$165:$P$214,1),$P$165:$P$214,0)),"") -> 0 | M92: =IFERROR(INDEX($N$165:$N$214,MATCH(LARGE($P$165:$P$214,1),$P$165:$P$214,0)),"") -> 56492 | N92: =IFERROR(INDEX($O$165:$O$214,MATCH(LARGE($P$165:$P$214,1),$P$165:$P$214,0)),"") -> 0.078548387
A93: 2 | B93: =IFERROR(INDEX($B$165:$B$214,MATCH(LARGE($P$165:$P$214,2),$P$165:$P$214,0)),"") -> Cameron Lund | C93: =IFERROR(INDEX($C$165:$C$214,MATCH(LARGE($P$165:$P$214,2),$P$165:$P$214,0)),"") -> Senior Enterprise AE | D93: =IFERROR(INDEX($D$165:$D$214,MATCH(LARGE($P$165:$P$214,2),$P$165:$P$214,0)),"") -> Strategic | E93: =IFERROR(INDEX($E$165:$E$214,MATCH(LARGE($P$165:$P$214,2),$P$165:$P$214,0)),"") -> LATAM | F93: =IFERROR(INDEX($G$165:$G$214,MATCH(LARGE($P$165:$P$214,2),$P$165:$P$214,0)),"") -> 575500 | G93: =IFERROR(INDEX($H$165:$H$214,MATCH(LARGE($P$165:$P$214,2),$P$165:$P$214,0)),"") -> 668200 | H93: =IFERROR(INDEX($I$165:$I$214,MATCH(LARGE($P$165:$P$214,2),$P$165:$P$214,0)),"") -> 1.1610773 | I93: =IFERROR(INDEX($J$165:$J$214,MATCH(LARGE($P$165:$P$214,2),$P$165:$P$214,0)),"") -> TRUE | J93: =IFERROR(INDEX($K$165:$K$214,MATCH(LARGE($P$165:$P$214,2),$P$165:$P$214,0)),"") -> 40285 | K93: =IFERROR(INDEX($L$165:$L$214,MATCH(LARGE($P$165:$P$214,2),$P$165:$P$214,0)),"") -> 10197 | L93: =IFERROR(INDEX($M$165:$M$214,MATCH(LARGE($P$165:$P$214,2),$P$165:$P$214,0)),"") -> 0 | M93: =IFERROR(INDEX($N$165:$N$214,MATCH(LARGE($P$165:$P$214,2),$P$165:$P$214,0)),"") -> 50482 | N93: =IFERROR(INDEX($O$165:$O$214,MATCH(LARGE($P$165:$P$214,2),$P$165:$P$214,0)),"") -> 0.075549237
A94: 3 | B94: =IFERROR(INDEX($B$165:$B$214,MATCH(LARGE($P$165:$P$214,3),$P$165:$P$214,0)),"") -> Sara Andersson | C94: =IFERROR(INDEX($C$165:$C$214,MATCH(LARGE($P$165:$P$214,3),$P$165:$P$214,0)),"") -> Senior Enterprise AE | D94: =IFERROR(INDEX($D$165:$D$214,MATCH(LARGE($P$165:$P$214,3),$P$165:$P$214,0)),"") -> Strategic | E94: =IFERROR(INDEX($E$165:$E$214,MATCH(LARGE($P$165:$P$214,3),$P$165:$P$214,0)),"") -> APAC | F94: =IFERROR(INDEX($G$165:$G$214,MATCH(LARGE($P$165:$P$214,3),$P$165:$P$214,0)),"") -> 575900 | G94: =IFERROR(INDEX($H$165:$H$214,MATCH(LARGE($P$165:$P$214,3),$P$165:$P$214,0)),"") -> 478200 | H94: =IFERROR(INDEX($I$165:$I$214,MATCH(LARGE($P$165:$P$214,3),$P$165:$P$214,0)),"") -> 0.83035249 | I94: =IFERROR(INDEX($J$165:$J$214,MATCH(LARGE($P$165:$P$214,3),$P$165:$P$214,0)),"") -> TRUE | J94: =IFERROR(INDEX($K$165:$K$214,MATCH(LARGE($P$165:$P$214,3),$P$165:$P$214,0)),"") -> 33474 | K94: =IFERROR(INDEX($L$165:$L$214,MATCH(LARGE($P$165:$P$214,3),$P$165:$P$214,0)),"") -> 0 | L94: =IFERROR(INDEX($M$165:$M$214,MATCH(LARGE($P$165:$P$214,3),$P$165:$P$214,0)),"") -> 0 | M94: =IFERROR(INDEX($N$165:$N$214,MATCH(LARGE($P$165:$P$214,3),$P$165:$P$214,0)),"") -> 33474 | N94: =IFERROR(INDEX($O$165:$O$214,MATCH(LARGE($P$165:$P$214,3),$P$165:$P$214,0)),"") -> 0.07
A95: 4 | B95: =IFERROR(INDEX($B$165:$B$214,MATCH(LARGE($P$165:$P$214,4),$P$165:$P$214,0)),"") -> Milo Weber | C95: =IFERROR(INDEX($C$165:$C$214,MATCH(LARGE($P$165:$P$214,4),$P$165:$P$214,0)),"") -> Enterprise AE | D95: =IFERROR(INDEX($D$165:$D$214,MATCH(LARGE($P$165:$P$214,4),$P$165:$P$214,0)),"") -> Enterprise | E95: =IFERROR(INDEX($E$165:$E$214,MATCH(LARGE($P$165:$P$214,4),$P$165:$P$214,0)),"") -> NAMER | F95: =IFERROR(INDEX($G$165:$G$214,MATCH(LARGE($P$165:$P$214,4),$P$165:$P$214,0)),"") -> 387900 | G95: =IFERROR(INDEX($H$165:$H$214,MATCH(LARGE($P$165:$P$214,4),$P$165:$P$214,0)),"") -> 473100 | H95: =IFERROR(INDEX($I$165:$I$214,MATCH(LARGE($P$165:$P$214,4),$P$165:$P$214,0)),"") -> 1.2196442 | I95: =IFERROR(INDEX($J$165:$J$214,MATCH(LARGE($P$165:$P$214,4),$P$165:$P$214,0)),"") -> TRUE | J95: =IFERROR(INDEX($K$165:$K$214,MATCH(LARGE($P$165:$P$214,4),$P$165:$P$214,0)),"") -> 23274 | K95: =IFERROR(INDEX($L$165:$L$214,MATCH(LARGE($P$165:$P$214,4),$P$165:$P$214,0)),"") -> 8520 | L95: =IFERROR(INDEX($M$165:$M$214,MATCH(LARGE($P$165:$P$214,4),$P$165:$P$214,0)),"") -> 0 | M95: =IFERROR(INDEX($N$165:$N$214,MATCH(LARGE($P$165:$P$214,4),$P$165:$P$214,0)),"") -> 31794 | N95: =IFERROR(INDEX($O$165:$O$214,MATCH(LARGE($P$165:$P$214,4),$P$165:$P$214,0)),"") -> 0.067203551
A96: 5 | B96: =IFERROR(INDEX($B$165:$B$214,MATCH(LARGE($P$165:$P$214,5),$P$165:$P$214,0)),"") -> Sam Schmidt | C96: =IFERROR(INDEX($C$165:$C$214,MATCH(LARGE($P$165:$P$214,5),$P$165:$P$214,0)),"") -> Enterprise AE | D96: =IFERROR(INDEX($D$165:$D$214,MATCH(LARGE($P$165:$P$214,5),$P$165:$P$214,0)),"") -> Enterprise | E96: =IFERROR(INDEX($E$165:$E$214,MATCH(LARGE($P$165:$P$214,5),$P$165:$P$214,0)),"") -> EMEA | F96: =IFERROR(INDEX($G$165:$G$214,MATCH(LARGE($P$165:$P$214,5),$P$165:$P$214,0)),"") -> 381100 | G96: =IFERROR(INDEX($H$165:$H$214,MATCH(LARGE($P$165:$P$214,5),$P$165:$P$214,0)),"") -> 450300 | H96: =IFERROR(INDEX($I$165:$I$214,MATCH(LARGE($P$165:$P$214,5),$P$165:$P$214,0)),"") -> 1.1815796 | I96: =IFERROR(INDEX($J$165:$J$214,MATCH(LARGE($P$165:$P$214,5),$P$165:$P$214,0)),"") -> TRUE | J96: =IFERROR(INDEX($K$165:$K$214,MATCH(LARGE($P$165:$P$214,5),$P$165:$P$214,0)),"") -> 22866 | K96: =IFERROR(INDEX($L$165:$L$214,MATCH(LARGE($P$165:$P$214,5),$P$165:$P$214,0)),"") -> 6920 | L96: =IFERROR(INDEX($M$165:$M$214,MATCH(LARGE($P$165:$P$214,5),$P$165:$P$214,0)),"") -> 0 | M96: =IFERROR(INDEX($N$165:$N$214,MATCH(LARGE($P$165:$P$214,5),$P$165:$P$214,0)),"") -> 29786 | N96: =IFERROR(INDEX($O$165:$O$214,MATCH(LARGE($P$165:$P$214,5),$P$165:$P$214,0)),"") -> 0.066147013
A97: 6 | B97: =IFERROR(INDEX($B$165:$B$214,MATCH(LARGE($P$165:$P$214,6),$P$165:$P$214,0)),"") -> Zara Duarte | C97: =IFERROR(INDEX($C$165:$C$214,MATCH(LARGE($P$165:$P$214,6),$P$165:$P$214,0)),"") -> Enterprise AE | D97: =IFERROR(INDEX($D$165:$D$214,MATCH(LARGE($P$165:$P$214,6),$P$165:$P$214,0)),"") -> Enterprise | E97: =IFERROR(INDEX($E$165:$E$214,MATCH(LARGE($P$165:$P$214,6),$P$165:$P$214,0)),"") -> NAMER | F97: =IFERROR(INDEX($G$165:$G$214,MATCH(LARGE($P$165:$P$214,6),$P$165:$P$214,0)),"") -> 380500 | G97: =IFERROR(INDEX($H$165:$H$214,MATCH(LARGE($P$165:$P$214,6),$P$165:$P$214,0)),"") -> 423000 | H97: =IFERROR(INDEX($I$165:$I$214,MATCH(LARGE($P$165:$P$214,6),$P$165:$P$214,0)),"") -> 1.1116951 | I97: =IFERROR(INDEX($J$165:$J$214,MATCH(LARGE($P$165:$P$214,6),$P$165:$P$214,0)),"") -> TRUE | J97: =IFERROR(INDEX($K$165:$K$214,MATCH(LARGE($P$165:$P$214,6),$P$165:$P$214,0)),"") -> 22830 | K97: =IFERROR(INDEX($L$165:$L$214,MATCH(LARGE($P$165:$P$214,6),$P$165:$P$214,0)),"") -> 4250 | L97: =IFERROR(INDEX($M$165:$M$214,MATCH(LARGE($P$165:$P$214,6),$P$165:$P$214,0)),"") -> 0 | M97: =IFERROR(INDEX($N$165:$N$214,MATCH(LARGE($P$165:$P$214,6),$P$165:$P$214,0)),"") -> 27080 | N97: =IFERROR(INDEX($O$165:$O$214,MATCH(LARGE($P$165:$P$214,6),$P$165:$P$214,0)),"") -> 0.064018913
A98: 7 | B98: =IFERROR(INDEX($B$165:$B$214,MATCH(LARGE($P$165:$P$214,7),$P$165:$P$214,0)),"") -> Erik Duarte | C98: =IFERROR(INDEX($C$165:$C$214,MATCH(LARGE($P$165:$P$214,7),$P$165:$P$214,0)),"") -> Mid-Market AE | D98: =IFERROR(INDEX($D$165:$D$214,MATCH(LARGE($P$165:$P$214,7),$P$165:$P$214,0)),"") -> Mid-Market | E98: =IFERROR(INDEX($E$165:$E$214,MATCH(LARGE($P$165:$P$214,7),$P$165:$P$214,0)),"") -> EMEA | F98: =IFERROR(INDEX($G$165:$G$214,MATCH(LARGE($P$165:$P$214,7),$P$165:$P$214,0)),"") -> 263800 | G98: =IFERROR(INDEX($H$165:$H$214,MATCH(LARGE($P$165:$P$214,7),$P$165:$P$214,0)),"") -> 397800 | H98: =IFERROR(INDEX($I$165:$I$214,MATCH(LARGE($P$165:$P$214,7),$P$165:$P$214,0)),"") -> 1.5079606 | I98: =IFERROR(INDEX($J$165:$J$214,MATCH(LARGE($P$165:$P$214,7),$P$165:$P$214,0)),"") -> TRUE | J98: =IFERROR(INDEX($K$165:$K$214,MATCH(LARGE($P$165:$P$214,7),$P$165:$P$214,0)),"") -> 13190 | K98: =IFERROR(INDEX($L$165:$L$214,MATCH(LARGE($P$165:$P$214,7),$P$165:$P$214,0)),"") -> 10552 | L98: =IFERROR(INDEX($M$165:$M$214,MATCH(LARGE($P$165:$P$214,7),$P$165:$P$214,0)),"") -> 231 | M98: =IFERROR(INDEX($N$165:$N$214,MATCH(LARGE($P$165:$P$214,7),$P$165:$P$214,0)),"") -> 23973 | N98: =IFERROR(INDEX($O$165:$O$214,MATCH(LARGE($P$165:$P$214,7),$P$165:$P$214,0)),"") -> 0.060263952
A99: 8 | B99: =IFERROR(INDEX($B$165:$B$214,MATCH(LARGE($P$165:$P$214,8),$P$165:$P$214,0)),"") -> Noah Kim | C99: =IFERROR(INDEX($C$165:$C$214,MATCH(LARGE($P$165:$P$214,8),$P$165:$P$214,0)),"") -> Enterprise AE | D99: =IFERROR(INDEX($D$165:$D$214,MATCH(LARGE($P$165:$P$214,8),$P$165:$P$214,0)),"") -> Enterprise | E99: =IFERROR(INDEX($E$165:$E$214,MATCH(LARGE($P$165:$P$214,8),$P$165:$P$214,0)),"") -> LATAM | F99: =IFERROR(INDEX($G$165:$G$214,MATCH(LARGE($P$165:$P$214,8),$P$165:$P$214,0)),"") -> 385300 | G99: =IFERROR(INDEX($H$165:$H$214,MATCH(LARGE($P$165:$P$214,8),$P$165:$P$214,0)),"") -> 369900 | H99: =IFERROR(INDEX($I$165:$I$214,MATCH(LARGE($P$165:$P$214,8),$P$165:$P$214,0)),"") -> 0.96003114 | I99: =IFERROR(INDEX($J$165:$J$214,MATCH(LARGE($P$165:$P$214,8),$P$165:$P$214,0)),"") -> TRUE | J99: =IFERROR(INDEX($K$165:$K$214,MATCH(LARGE($P$165:$P$214,8),$P$165:$P$214,0)),"") -> 22194 | K99: =IFERROR(INDEX($L$165:$L$214,MATCH(LARGE($P$165:$P$214,8),$P$165:$P$214,0)),"") -> 0 | L99: =IFERROR(INDEX($M$165:$M$214,MATCH(LARGE($P$165:$P$214,8),$P$165:$P$214,0)),"") -> 0 | M99: =IFERROR(INDEX($N$165:$N$214,MATCH(LARGE($P$165:$P$214,8),$P$165:$P$214,0)),"") -> 22194 | N99: =IFERROR(INDEX($O$165:$O$214,MATCH(LARGE($P$165:$P$214,8),$P$165:$P$214,0)),"") -> 0.06
A100: 9 | B100: =IFERROR(INDEX($B$165:$B$214,MATCH(LARGE($P$165:$P$214,9),$P$165:$P$214,0)),"") -> Yuki Dubois | C100: =IFERROR(INDEX($C$165:$C$214,MATCH(LARGE($P$165:$P$214,9),$P$165:$P$214,0)),"") -> Mid-Market AE | D100: =IFERROR(INDEX($D$165:$D$214,MATCH(LARGE($P$165:$P$214,9),$P$165:$P$214,0)),"") -> Mid-Market | E100: =IFERROR(INDEX($E$165:$E$214,MATCH(LARGE($P$165:$P$214,9),$P$165:$P$214,0)),"") -> LATAM | F100: =IFERROR(INDEX($G$165:$G$214,MATCH(LARGE($P$165:$P$214,9),$P$165:$P$214,0)),"") -> 264100 | G100: =IFERROR(INDEX($H$165:$H$214,MATCH(LARGE($P$165:$P$214,9),$P$165:$P$214,0)),"") -> 360400 | H100: =IFERROR(INDEX($I$165:$I$214,MATCH(LARGE($P$165:$P$214,9),$P$165:$P$214,0)),"") -> 1.3646346 | I100: =IFERROR(INDEX($J$165:$J$214,MATCH(LARGE($P$165:$P$214,9),$P$165:$P$214,0)),"") -> TRUE | J100: =IFERROR(INDEX($K$165:$K$214,MATCH(LARGE($P$165:$P$214,9),$P$165:$P$214,0)),"") -> 13205 | K100: =IFERROR(INDEX($L$165:$L$214,MATCH(LARGE($P$165:$P$214,9),$P$165:$P$214,0)),"") -> 7704 | L100: =IFERROR(INDEX($M$165:$M$214,MATCH(LARGE($P$165:$P$214,9),$P$165:$P$214,0)),"") -> 0 | M100: =IFERROR(INDEX($N$165:$N$214,MATCH(LARGE($P$165:$P$214,9),$P$165:$P$214,0)),"") -> 20909 | N100: =IFERROR(INDEX($O$165:$O$214,MATCH(LARGE($P$165:$P$214,9),$P$165:$P$214,0)),"") -> 0.058016093
A101: 10 | B101: =IFERROR(INDEX($B$165:$B$214,MATCH(LARGE($P$165:$P$214,10),$P$165:$P$214,0)),"") -> Felix Okafor | C101: =IFERROR(INDEX($C$165:$C$214,MATCH(LARGE($P$165:$P$214,10),$P$165:$P$214,0)),"") -> Mid-Market AE | D101: =IFERROR(INDEX($D$165:$D$214,MATCH(LARGE($P$165:$P$214,10),$P$165:$P$214,0)),"") -> Mid-Market | E101: =IFERROR(INDEX($E$165:$E$214,MATCH(LARGE($P$165:$P$214,10),$P$165:$P$214,0)),"") -> EMEA | F101: =IFERROR(INDEX($G$165:$G$214,MATCH(LARGE($P$165:$P$214,10),$P$165:$P$214,0)),"") -> 263400 | G101: =IFERROR(INDEX($H$165:$H$214,MATCH(LARGE($P$165:$P$214,10),$P$165:$P$214,0)),"") -> 354500 | H101: =IFERROR(INDEX($I$165:$I$214,MATCH(LARGE($P$165:$P$214,10),$P$165:$P$214,0)),"") -> 1.3458618 | I101: =IFERROR(INDEX($J$165:$J$214,MATCH(LARGE($P$165:$P$214,10),$P$165:$P$214,0)),"") -> TRUE | J101: =IFERROR(INDEX($K$165:$K$214,MATCH(LARGE($P$165:$P$214,10),$P$165:$P$214,0)),"") -> 13170 | K101: =IFERROR(INDEX($L$165:$L$214,MATCH(LARGE($P$165:$P$214,10),$P$165:$P$214,0)),"") -> 7288 | L101: =IFERROR(INDEX($M$165:$M$214,MATCH(LARGE($P$165:$P$214,10),$P$165:$P$214,0)),"") -> 0 | M101: =IFERROR(INDEX($N$165:$N$214,MATCH(LARGE($P$165:$P$214,10),$P$165:$P$214,0)),"") -> 20458 | N101: =IFERROR(INDEX($O$165:$O$214,MATCH(LARGE($P$165:$P$214,10),$P$165:$P$214,0)),"") -> 0.05770945
A102: 11 | B102: =IFERROR(INDEX($B$165:$B$214,MATCH(LARGE($P$165:$P$214,11),$P$165:$P$214,0)),"") -> Ivy Adler | C102: =IFERROR(INDEX($C$165:$C$214,MATCH(LARGE($P$165:$P$214,11),$P$165:$P$214,0)),"") -> Mid-Market AE | D102: =IFERROR(INDEX($D$165:$D$214,MATCH(LARGE($P$165:$P$214,11),$P$165:$P$214,0)),"") -> Mid-Market | E102: =IFERROR(INDEX($E$165:$E$214,MATCH(LARGE($P$165:$P$214,11),$P$165:$P$214,0)),"") -> APAC | F102: =IFERROR(INDEX($G$165:$G$214,MATCH(LARGE($P$165:$P$214,11),$P$165:$P$214,0)),"") -> 267800 | G102: =IFERROR(INDEX($H$165:$H$214,MATCH(LARGE($P$165:$P$214,11),$P$165:$P$214,0)),"") -> 319800 | H102: =IFERROR(INDEX($I$165:$I$214,MATCH(LARGE($P$165:$P$214,11),$P$165:$P$214,0)),"") -> 1.1941748 | I102: =IFERROR(INDEX($J$165:$J$214,MATCH(LARGE($P$165:$P$214,11),$P$165:$P$214,0)),"") -> TRUE | J102: =IFERROR(INDEX($K$165:$K$214,MATCH(LARGE($P$165:$P$214,11),$P$165:$P$214,0)),"") -> 13390 | K102: =IFERROR(INDEX($L$165:$L$214,MATCH(LARGE($P$165:$P$214,11),$P$165:$P$214,0)),"") -> 4160 | L102: =IFERROR(INDEX($M$165:$M$214,MATCH(LARGE($P$165:$P$214,11),$P$165:$P$214,0)),"") -> 0 | M102: =IFERROR(INDEX($N$165:$N$214,MATCH(LARGE($P$165:$P$214,11),$P$165:$P$214,0)),"") -> 17550 | N102: =IFERROR(INDEX($O$165:$O$214,MATCH(LARGE($P$165:$P$214,11),$P$165:$P$214,0)),"") -> 0.054878049
A103: 12 | B103: =IFERROR(INDEX($B$165:$B$214,MATCH(LARGE($P$165:$P$214,12),$P$165:$P$214,0)),"") -> Jonas Sato | C103: =IFERROR(INDEX($C$165:$C$214,MATCH(LARGE($P$165:$P$214,12),$P$165:$P$214,0)),"") -> Mid-Market AE | D103: =IFERROR(INDEX($D$165:$D$214,MATCH(LARGE($P$165:$P$214,12),$P$165:$P$214,0)),"") -> Mid-Market | E103: =IFERROR(INDEX($E$165:$E$214,MATCH(LARGE($P$165:$P$214,12),$P$165:$P$214,0)),"") -> LATAM | F103: =IFERROR(INDEX($G$165:$G$214,MATCH(LARGE($P$165:$P$214,12),$P$165:$P$214,0)),"") -> 262900 | G103: =IFERROR(INDEX($H$165:$H$214,MATCH(LARGE($P$165:$P$214,12),$P$165:$P$214,0)),"") -> 271800 | H103: =IFERROR(INDEX($I$165:$I$214,MATCH(LARGE($P$165:$P$214,12),$P$165:$P$214,0)),"") -> 1.0338532 | I103: =IFERROR(INDEX($J$165:$J$214,MATCH(LARGE($P$165:$P$214,12),$P$165:$P$214,0)),"") -> TRUE | J103: =IFERROR(INDEX($K$165:$K$214,MATCH(LARGE($P$165:$P$214,12),$P$165:$P$214,0)),"") -> 13145 | K103: =IFERROR(INDEX($L$165:$L$214,MATCH(LARGE($P$165:$P$214,12),$P$165:$P$214,0)),"") -> 712 | L103: =IFERROR(INDEX($M$165:$M$214,MATCH(LARGE($P$165:$P$214,12),$P$165:$P$214,0)),"") -> 0 | M103: =IFERROR(INDEX($N$165:$N$214,MATCH(LARGE($P$165:$P$214,12),$P$165:$P$214,0)),"") -> 13857 | N103: =IFERROR(INDEX($O$165:$O$214,MATCH(LARGE($P$165:$P$214,12),$P$165:$P$214,0)),"") -> 0.05098234
...

Sheet Pipeline Coverage
A1: PIPELINE COVERAGE & GAP-TO-GOAL
A2: ="Goal period: "&D5&" | Reporting month: "&TEXT(A5,"mmm yyyy")&" | Target coverage: "&TEXT(G5,"0.0")&"x | Prepared September 1, 2026" -> Goal period: Rest of Quarter | Reporting month: Aug 2025 | Target coverage: 3.0x | Prepared September 1, 2026
A4: REPORTING MONTH (drop down) | D4: GOAL PERIOD (drop down) | G4: TARGET COVERAGE RATIO | I4: DATA THROUGH
A5: 45870 | D5: Rest of Quarter | G5: 3 | I5: =TEXT(MAX(Fact_Quota!$B:$B),"mmm yyyy") -> Dec 2025
A7: ="PIPELINE COVERAGE SUMMARY FOR: " &D5&"" -> PIPELINE COVERAGE SUMMARY FOR: Rest of Quarter
A9: TOTAL GAP TO GOAL | D9: TOTAL OPEN PIPELINE | G9: COMPANY COVERAGE RATIO | J9: COMPANY REQUIRED WIN RATE
A10: =SUM($H$137:$H$186) -> 1603100 | D10: =SUM($I$137:$I$186) -> 7275100 | G10: =IFERROR(SUM($I$137:$I$186)/SUM($H$137:$H$186),"") -> 4.5381448 | J10: =IFERROR(SUM($H$137:$H$186)/SUM($I$137:$I$186),"") -> 0.22035436
A11: remaining quota, goal period | D11: current snapshot, all open deals | G11: open pipeline ÷ gap to goal | J11: % of open pipeline that must convert
A13: REPS BELOW TARGET COVERAGE | D13: REPS AT RISK (BELOW OWN PACE) | G13: REPS GOAL ALREADY ACHIEVED | J13: AVG COVERAGE RATIO (ACTIVE, WITH GAP)
A14: =COUNTIFS($E$137:$E$186,"Active",$H$137:$H$186,">0",$J$137:$J$186,"<"&G5) -> 20 | D14: =COUNTIFS($O$137:$O$186,"At Risk – Below Pace") -> 22 | G14: =COUNTIFS($O$137:$O$186,"Goal Achieved") -> 9 | J14: =IFERROR(AVERAGEIFS($J$137:$J$186,$H$137:$H$186,">0",$E$137:$E$186,"Active"),"") -> 4.3845656
A15: active reps under the target ratio | D15: required win rate exceeds own historical rate | G15: quota already met for the goal period | J15: unweighted average across at-risk reps
A18: ="COVERAGE BY TEAM & REGION for: " &D5&"" -> COVERAGE BY TEAM & REGION for: Rest of Quarter
A35: Team | B35: Active Reps | C35: Gap to Goal | D35: Open Pipeline | E35: Coverage Ratio | F35: Target | H35: Region | I35: Active Reps | J35: Gap to Goal | K35: Open Pipeline | L35: Coverage Ratio | M35: Target
A36: Inside Sales | B36: =COUNTIFS($C$137:$C$186,A36,$E$137:$E$186,"Active") -> 21 | C36: =SUMIF($C$137:$C$186,A36,$H$137:$H$186) -> 439200 | D36: =SUMIF($C$137:$C$186,A36,$I$137:$I$186) -> 734400 | E36: =IFERROR(D36/C36,"") -> 1.6721311 | F36: =G5 -> 3 | H36: NAMER | I36: =COUNTIFS($D$137:$D$186,H36,$E$137:$E$186,"Active") -> 12 | J36: =SUMIF($D$137:$D$186,H36,$H$137:$H$186) -> 530100 | K36: =SUMIF($D$137:$D$186,H36,$I$137:$I$186) -> 3008300 | L36: =IFERROR(K36/J36,"") -> 5.674967 | M36: =G5 -> 3
A37: Mid-Market | B37: =COUNTIFS($C$137:$C$186,A37,$E$137:$E$186,"Active") -> 13 | C37: =SUMIF($C$137:$C$186,A37,$H$137:$H$186) -> 426700 | D37: =SUMIF($C$137:$C$186,A37,$I$137:$I$186) -> 1245800 | E37: =IFERROR(D37/C37,"") -> 2.9196157 | F37: =G5 -> 3 | H37: EMEA | I37: =COUNTIFS($D$137:$D$186,H37,$E$137:$E$186,"Active") -> 10 | J37: =SUMIF($D$137:$D$186,H37,$H$137:$H$186) -> 189800 | K37: =SUMIF($D$137:$D$186,H37,$I$137:$I$186) -> 1052200 | L37: =IFERROR(K37/J37,"") -> 5.5437302 | M37: =G5 -> 3
A38: Enterprise | B38: =COUNTIFS($C$137:$C$186,A38,$E$137:$E$186,"Active") -> 5 | C38: =SUMIF($C$137:$C$186,A38,$H$137:$H$186) -> 231800 | D38: =SUMIF($C$137:$C$186,A38,$I$137:$I$186) -> 2761100 | E38: =IFERROR(D38/C38,"") -> 11.911562 | F38: =G5 -> 3 | H38: APAC | I38: =COUNTIFS($D$137:$D$186,H38,$E$137:$E$186,"Active") -> 13 | J38: =SUMIF($D$137:$D$186,H38,$H$137:$H$186) -> 531100 | K38: =SUMIF($D$137:$D$186,H38,$I$137:$I$186) -> 2064100 | L38: =IFERROR(K38/J38,"") -> 3.8864621 | M38: =G5 -> 3
A39: Strategic | B39: =COUNTIFS($C$137:$C$186,A39,$E$137:$E$186,"Active") -> 3 | C39: =SUMIF($C$137:$C$186,A39,$H$137:$H$186) -> 505400 | D39: =SUMIF($C$137:$C$186,A39,$I$137:$I$186) -> 2533800 | E39: =IFERROR(D39/C39,"") -> 5.0134547 | F39: =G5 -> 3 | H39: LATAM | I39: =COUNTIFS($D$137:$D$186,H39,$E$137:$E$186,"Active") -> 7 | J39: =SUMIF($D$137:$D$186,H39,$H$137:$H$186) -> 352100 | K39: =SUMIF($D$137:$D$186,H39,$I$137:$I$186) -> 1150500 | L39: =IFERROR(K39/J39,"") -> 3.2675376 | M39: =G5 -> 3
A41: PER-REP COVERAGE RANKED BY RISK (LOWEST COVERAGE to HIGHEST COVERAGE)
B61: Data model: Dim_Reps, Fact_Quota, Fact_Pipeline (all values USD-normalized). Gap to Goal = quota for the selected goal period minus bookings won so far in that period (floored at $0). Open Pipeline is a current snapshot of all open deals (not limited to the goal period). Coverage Ratio = Open Pipeline ÷ Gap to Goal; Required Win Rate = Gap to Goal ÷ Open Pipeline (the share of open pipeline that must convert to close the gap), compared against each rep's own trailing-12-month win rate (falls back to the company win rate for reps with few closed deals). Target Coverage Ratio above is an editable assumption/benchmark, not a guarantee. All figures recalculate automatically from the controls above. Supporting calculations are on this sheet below row 300 (grouped/collapsed).
B64: Rank | C64: Rep Name | D64: Team | E64: Region | F64: Gap to Goal | G64: Open Pipeline | H64: Coverage Ratio | I64: Required Win Rate | J64: Historical Win Rate | K64: Status
B65: 1 | C65: =IFERROR(INDEX($B$137:$B$186,MATCH(LARGE($P$137:$P$186,1),$P$137:$P$186,0)),"") -> Petra Larsen | D65: =IFERROR(INDEX($C$137:$C$186,MATCH(LARGE($P$137:$P$186,1),$P$137:$P$186,0)),"") -> Inside Sales | E65: =IFERROR(INDEX($D$137:$D$186,MATCH(LARGE($P$137:$P$186,1),$P$137:$P$186,0)),"") -> EMEA | F65: =IFERROR(INDEX($H$137:$H$186,MATCH(LARGE($P$137:$P$186,1),$P$137:$P$186,0)),"") -> 47400 | G65: =IFERROR(INDEX($I$137:$I$186,MATCH(LARGE($P$137:$P$186,1),$P$137:$P$186,0)),"") -> 28700 | H65: =IFERROR(INDEX($J$137:$J$186,MATCH(LARGE($P$137:$P$186,1),$P$137:$P$186,0)),"") -> 0.60548523 | I65: =IFERROR(INDEX($N$137:$N$186,MATCH(LARGE($P$137:$P$186,1),$P$137:$P$186,0)),"") -> 1.6515679 | J65: =IFERROR(INDEX($M$137:$M$186,MATCH(LARGE($P$137:$P$186,1),$P$137:$P$186,0)),"") -> 0.2745098 | K65: =IFERROR(INDEX($O$137:$O$186,MATCH(LARGE($P$137:$P$186,1),$P$137:$P$186,0)),"") -> At Risk – Below Pace
B66: 2 | C66: =IFERROR(INDEX($B$137:$B$186,MATCH(LARGE($P$137:$P$186,2),$P$137:$P$186,0)),"") -> Liam Castro | D66: =IFERROR(INDEX($C$137:$C$186,MATCH(LARGE($P$137:$P$186,2),$P$137:$P$186,0)),"") -> Inside Sales | E66: =IFERROR(INDEX($D$137:$D$186,MATCH(LARGE($P$137:$P$186,2),$P$137:$P$186,0)),"") -> NAMER | F66: =IFERROR(INDEX($H$137:$H$186,MATCH(LARGE($P$137:$P$186,2),$P$137:$P$186,0)),"") -> 20600 | G66: =IFERROR(INDEX($I$137:$I$186,MATCH(LARGE($P$137:$P$186,2),$P$137:$P$186,0)),"") -> 14500 | H66: =IFERROR(INDEX($J$137:$J$186,MATCH(LARGE($P$137:$P$186,2),$P$137:$P$186,0)),"") -> 0.7038835 | I66: =IFERROR(INDEX($N$137:$N$186,MATCH(LARGE($P$137:$P$186,2),$P$137:$P$186,0)),"") -> 1.4206897 | J66: =IFERROR(INDEX($M$137:$M$186,MATCH(LARGE($P$137:$P$186,2),$P$137:$P$186,0)),"") -> 0.36521739 | K66: =IFERROR(INDEX($O$137:$O$186,MATCH(LARGE($P$137:$P$186,2),$P$137:$P$186,0)),"") -> At Risk – Below Pace
B67: 3 | C67: =IFERROR(INDEX($B$137:$B$186,MATCH(LARGE($P$137:$P$186,3),$P$137:$P$186,0)),"") -> Karim Rossi | D67: =IFERROR(INDEX($C$137:$C$186,MATCH(LARGE($P$137:$P$186,3),$P$137:$P$186,0)),"") -> Inside Sales | E67: =IFERROR(INDEX($D$137:$D$186,MATCH(LARGE($P$137:$P$186,3),$P$137:$P$186,0)),"") -> NAMER | F67: =IFERROR(INDEX($H$137:$H$186,MATCH(LARGE($P$137:$P$186,3),$P$137:$P$186,0)),"") -> 21500 | G67: =IFERROR(INDEX($I$137:$I$186,MATCH(LARGE($P$137:$P$186,3),$P$137:$P$186,0)),"") -> 15600 | H67: =IFERROR(INDEX($J$137:$J$186,MATCH(LARGE($P$137:$P$186,3),$P$137:$P$186,0)),"") -> 0.7255814 | I67: =IFERROR(INDEX($N$137:$N$186,MATCH(LARGE($P$137:$P$186,3),$P$137:$P$186,0)),"") -> 1.3782051 | J67: =IFERROR(INDEX($M$137:$M$186,MATCH(LARGE($P$137:$P$186,3),$P$137:$P$186,0)),"") -> 0.3592233 | K67: =IFERROR(INDEX($O$137:$O$186,MATCH(LARGE($P$137:$P$186,3),$P$137:$P$186,0)),"") -> At Risk – Below Pace
B68: 4 | C68: =IFERROR(INDEX($B$137:$B$186,MATCH(LARGE($P$137:$P$186,4),$P$137:$P$186,0)),"") -> Ben Silva | D68: =IFERROR(INDEX($C$137:$C$186,MATCH(LARGE($P$137:$P$186,4),$P$137:$P$186,0)),"") -> Inside Sales | E68: =IFERROR(INDEX($D$137:$D$186,MATCH(LARGE($P$137:$P$186,4),$P$137:$P$186,0)),"") -> LATAM | F68: =IFERROR(INDEX($H$137:$H$186,MATCH(LARGE($P$137:$P$186,4),$P$137:$P$186,0)),"") -> 16200 | G68: =IFERROR(INDEX($I$137:$I$186,MATCH(LARGE($P$137:$P$186,4),$P$137:$P$186,0)),"") -> 12500 | H68: =IFERROR(INDEX($J$137:$J$186,MATCH(LARGE($P$137:$P$186,4),$P$137:$P$186,0)),"") -> 0.77160494 | I68: =IFERROR(INDEX($N$137:$N$186,MATCH(LARGE($P$137:$P$186,4),$P$137:$P$186,0)),"") -> 1.296 | J68: =IFERROR(INDEX($M$137:$M$186,MATCH(LARGE($P$137:$P$186,4),$P$137:$P$186,0)),"") -> 0.3490566 | K68: =IFERROR(INDEX($O$137:$O$186,MATCH(LARGE($P$137:$P$186,4),$P$137:$P$186,0)),"") -> At Risk – Below Pace
B69: 5 | C69: =IFERROR(INDEX($B$137:$B$186,MATCH(LARGE($P$137:$P$186,5),$P$137:$P$186,0)),"") -> Olivia Cohen | D69: =IFERROR(INDEX($C$137:$C$186,MATCH(LARGE($P$137:$P$186,5),$P$137:$P$186,0)),"") -> Mid-Market | E69: =IFERROR(INDEX($D$137:$D$186,MATCH(LARGE($P$137:$P$186,5),$P$137:$P$186,0)),"") -> APAC | F69: =IFERROR(INDEX($H$137:$H$186,MATCH(LARGE($P$137:$P$186,5),$P$137:$P$186,0)),"") -> 46900 | G69: =IFERROR(INDEX($I$137:$I$186,MATCH(LARGE($P$137:$P$186,5),$P$137:$P$186,0)),"") -> 38100 | H69: =IFERROR(INDEX($J$137:$J$186,MATCH(LARGE($P$137:$P$186,5),$P$137:$P$186,0)),"") -> 0.81236674 | I69: =IFERROR(INDEX($N$137:$N$186,MATCH(LARGE($P$137:$P$186,5),$P$137:$P$186,0)),"") -> 1.2309711 | J69: =IFERROR(INDEX($M$137:$M$186,MATCH(LARGE($P$137:$P$186,5),$P$137:$P$186,0)),"") -> 0.20967742 | K69: =IFERROR(INDEX($O$137:$O$186,MATCH(LARGE($P$137:$P$186,5),$P$137:$P$186,0)),"") -> At Risk – Below Pace
B70: 6 | C70: =IFERROR(INDEX($B$137:$B$186,MATCH(LARGE($P$137:$P$186,6),$P$137:$P$186,0)),"") -> Karim Rivera | D70: =IFERROR(INDEX($C$137:$C$186,MATCH(LARGE($P$137:$P$186,6),$P$137:$P$186,0)),"") -> Mid-Market | E70: =IFERROR(INDEX($D$137:$D$186,MATCH(LARGE($P$137:$P$186,6),$P$137:$P$186,0)),"") -> APAC | F70: =IFERROR(INDEX($H$137:$H$186,MATCH(LARGE($P$137:$P$186,6),$P$137:$P$186,0)),"") -> 61900 | G70: =IFERROR(INDEX($I$137:$I$186,MATCH(LARGE($P$137:$P$186,6),$P$137:$P$186,0)),"") -> 50800 | H70: =IFERROR(INDEX($J$137:$J$186,MATCH(LARGE($P$137:$P$186,6),$P$137:$P$186,0)),"") -> 0.82067851 | I70: =IFERROR(INDEX($N$137:$N$186,MATCH(LARGE($P$137:$P$186,6),$P$137:$P$186,0)),"") -> 1.2185039 | J70: =IFERROR(INDEX($M$137:$M$186,MATCH(LARGE($P$137:$P$186,6),$P$137:$P$186,0)),"") -> 0 | K70: =IFERROR(INDEX($O$137:$O$186,MATCH(LARGE($P$137:$P$186,6),$P$137:$P$186,0)),"") -> At Risk – Below Pace
B71: 7 | C71: =IFERROR(INDEX($B$137:$B$186,MATCH(LARGE($P$137:$P$186,7),$P$137:$P$186,0)),"") -> Milo Castro | D71: =IFERROR(INDEX($C$137:$C$186,MATCH(LARGE($P$137:$P$186,7),$P$137:$P$186,0)),"") -> Inside Sales | E71: =IFERROR(INDEX($D$137:$D$186,MATCH(LARGE($P$137:$P$186,7),$P$137:$P$186,0)),"") -> LATAM | F71: =IFERROR(INDEX($H$137:$H$186,MATCH(LARGE($P$137:$P$186,7),$P$137:$P$186,0)),"") -> 33600 | G71: =IFERROR(INDEX($I$137:$I$186,MATCH(LARGE($P$137:$P$186,7),$P$137:$P$186,0)),"") -> 32900 | H71: =IFERROR(INDEX($J$137:$J$186,MATCH(LARGE($P$137:$P$186,7),$P$137:$P$186,0)),"") -> 0.97916667 | I71: =IFERROR(INDEX($N$137:$N$186,MATCH(LARGE($P$137:$P$186,7),$P$137:$P$186,0)),"") -> 1.0212766 | J71: =IFERROR(INDEX($M$137:$M$186,MATCH(LARGE($P$137:$P$186,7),$P$137:$P$186,0)),"") -> 0.41880342 | K71: =IFERROR(INDEX($O$137:$O$186,MATCH(LARGE($P$137:$P$186,7),$P$137:$P$186,0)),"") -> At Risk – Below Pace
B72: 8 | C72: =IFERROR(INDEX($B$137:$B$186,MATCH(LARGE($P$137:$P$186,8),$P$137:$P$186,0)),"") -> Kenji Weber | D72: =IFERROR(INDEX($C$137:$C$186,MATCH(LARGE($P$137:$P$186,8),$P$137:$P$186,0)),"") -> Inside Sales | E72: =IFERROR(INDEX($D$137:$D$186,MATCH(LARGE($P$137:$P$186,8),$P$137:$P$186,0)),"") -> APAC | F72: =IFERROR(INDEX($H$137:$H$186,MATCH(LARGE($P$137:$P$186,8),$P$137:$P$186,0)),"") -> 31000 | G72: =IFERROR(INDEX($I$137:$I$186,MATCH(LARGE($P$137:$P$186,8),$P$137:$P$186,0)),"") -> 34000 | H72: =IFERROR(INDEX($J$137:$J$186,MATCH(LARGE($P$137:$P$186,8),$P$137:$P$186,0)),"") -> 1.0967742 | I72: =IFERROR(INDEX($N$137:$N$186,MATCH(LARGE($P$137:$P$186,8),$P$137:$P$186,0)),"") -> 0.91176471 | J72: =IFERROR(INDEX($M$137:$M$186,MATCH(LARGE($P$137:$P$186,8),$P$137:$P$186,0)),"") -> 0.37323944 | K72: =IFERROR(INDEX($O$137:$O$186,MATCH(LARGE($P$137:$P$186,8),$P$137:$P$186,0)),"") -> At Risk – Below Pace
B73: 9 | C73: =IFERROR(INDEX($B$137:$B$186,MATCH(LARGE($P$137:$P$186,9),$P$137:$P$186,0)),"") -> Lucas Okafor | D73: =IFERROR(INDEX($C$137:$C$186,MATCH(LARGE($P$137:$P$186,9),$P$137:$P$186,0)),"") -> Inside Sales | E73: =IFERROR(INDEX($D$137:$D$186,MATCH(LARGE($P$137:$P$186,9),$P$137:$P$186,0)),"") -> APAC | F73: =IFERROR(INDEX($H$137:$H$186,MATCH(LARGE($P$137:$P$186,9),$P$137:$P$186,0)),"") -> 31000 | G73: =IFERROR(INDEX($I$137:$I$186,MATCH(LARGE($P$137:$P$186,9),$P$137:$P$186,0)),"") -> 34200 | H73: =IFERROR(INDEX($J$137:$J$186,MATCH(LARGE($P$137:$P$186,9),$P$137:$P$186,0)),"") -> 1.1032258 | I73: =IFERROR(INDEX($N$137:$N$186,MATCH(LARGE($P$137:$P$186,9),$P$137:$P$186,0)),"") -> 0.90643275 | J73: =IFERROR(INDEX($M$137:$M$186,MATCH(LARGE($P$137:$P$186,9),$P$137:$P$186,0)),"") -> 0.46666667 | K73: =IFERROR(INDEX($O$137:$O$186,MATCH(LARGE($P$137:$P$186,9),$P$137:$P$186,0)),"") -> At Risk – Below Pace
B74: 10 | C74: =IFERROR(INDEX($B$137:$B$186,MATCH(LARGE($P$137:$P$186,10),$P$137:$P$186,0)),"") -> Lea Weber | D74: =IFERROR(INDEX($C$137:$C$186,MATCH(LARGE($P$137:$P$186,10),$P$137:$P$186,0)),"") -> Inside Sales | E74: =IFERROR(INDEX($D$137:$D$186,MATCH(LARGE($P$137:$P$186,10),$P$137:$P$186,0)),"") -> EMEA | F74: =IFERROR(INDEX($H$137:$H$186,MATCH(LARGE($P$137:$P$186,10),$P$137:$P$186,0)),"") -> 13700 | G74: =IFERROR(INDEX($I$137:$I$186,MATCH(LARGE($P$137:$P$186,10),$P$137:$P$186,0)),"") -> 17400 | H74: =IFERROR(INDEX($J$137:$J$186,MATCH(LARGE($P$137:$P$186,10),$P$137:$P$186,0)),"") -> 1.270073 | I74: =IFERROR(INDEX($N$137:$N$186,MATCH(LARGE($P$137:$P$186,10),$P$137:$P$186,0)),"") -> 0.78735632 | J74: =IFERROR(INDEX($M$137:$M$186,MATCH(LARGE($P$137:$P$186,10),$P$137:$P$186,0)),"") -> 0.36153846 | K74: =IFERROR(INDEX($O$137:$O$186,MATCH(LARGE($P$137:$P$186,10),$P$137:$P$186,0)),"") -> At Risk – Below Pace
B75: 11 | C75: =IFERROR(INDEX($B$137:$B$186,MATCH(LARGE($P$137:$P$186,11),$P$137:$P$186,0)),"") -> Rafael Weber | D75: =IFERROR(INDEX($C$137:$C$186,MATCH(LARGE($P$137:$P$186,11),$P$137:$P$186,0)),"") -> Mid-Market | E75: =IFERROR(INDEX($D$137:$D$186,MATCH(LARGE($P$137:$P$186,11),$P$137:$P$186,0)),"") -> APAC | F75: =IFERROR(INDEX($H$137:$H$186,MATCH(LARGE($P$137:$P$186,11),$P$137:$P$186,0)),"") -> 53900 | G75: =IFERROR(INDEX($I$137:$I$186,MATCH(LARGE($P$137:$P$186,11),$P$137:$P$186,0)),"") -> 88600 | H75: =IFERROR(INDEX($J$137:$J$186,MATCH(LARGE($P$137:$P$186,11),$P$137:$P$186,0)),"") -> 1.6437848 | I75: =IFERROR(INDEX($N$137:$N$186,MATCH(LARGE($P$137:$P$186,11),$P$137:$P$186,0)),"") -> 0.60835214 | J75: =IFERROR(INDEX($M$137:$M$186,MATCH(LARGE($P$137:$P$186,11),$P$137:$P$186,0)),"") -> 0.22222222 | K75: =IFERROR(INDEX($O$137:$O$186,MATCH(LARGE($P$137:$P$186,11),$P$137:$P$186,0)),"") -> At Risk – Below Pace
B76: 12 | C76: =IFERROR(INDEX($B$137:$B$186,MATCH(LARGE($P$137:$P$186,12),$P$137:$P$186,0)),"") -> Ana Kim | D76: =IFERROR(INDEX($C$137:$C$186,MATCH(LARGE($P$137:$P$186,12),$P$137:$P$186,0)),"") -> Mid-Market | E76: =IFERROR(INDEX($D$137:$D$186,MATCH(LARGE($P$137:$P$186,12),$P$137:$P$186,0)),"") -> APAC | F76: =IFERROR(INDEX($H$137:$H$186,MATCH(LARGE($P$137:$P$186,12),$P$137:$P$186,0)),"") -> 35100 | G76: =IFERROR(INDEX($I$137:$I$186,MATCH(LARGE($P$137:$P$186,12),$P$137:$P$186,0)),"") -> 61400 | H76: =IFERROR(INDEX($J$137:$J$186,MATCH(LARGE($P$137:$P$186,12),$P$137:$P$186,0)),"") -> 1.7492877 | I76: =IFERROR(INDEX($N$137:$N$186,MATCH(LARGE($P$137:$P$186,12),$P$137:$P$186,0)),"") -> 0.57166124 | J76: =IFERROR(INDEX($M$137:$M$186,MATCH(LARGE($P$137:$P$186,12),$P$137:$P$186,0)),"") -> 0.16666667 | K76: =IFERROR(INDEX($O$137:$O$186,MATCH(LARGE($P$137:$P$186,12),$P$137:$P$186,0)),"") -> At Risk – Below Pace
B77: 13 | C77: =IFERROR(INDEX($B$137:$B$186,MATCH(LARGE($P$137:$P$186,13),$P$137:$P$186,0)),"") -> Hugo Santos | D77: =IFERROR(INDEX($C$137:$C$186,MATCH(LARGE($P$137:$P$186,13),$P$137:$P$186,0)),"") -> Inside Sales | E77: =IFERROR(INDEX($D$137:$D$186,MATCH(LARGE($P$137:$P$186,13),$P$137:$P$186,0)),"") -> EMEA | F77: =IFERROR(INDEX($H$137:$H$186,MATCH(LARGE($P$137:$P$186,13),$P$137:$P$186,0)),"") -> 28700 | G77: =IFERROR(INDEX($I$137:$I$186,MATCH(LARGE($P$137:$P$186,13),$P$137:$P$186,0)),"") -> 52600 | H77: =IFERROR(INDEX($J$137:$J$186,MATCH(LARGE($P$137:$P$186,13),$P$137:$P$186,0)),"") -> 1.8327526 | I77: =IFERROR(INDEX($N$137:$N$186,MATCH(LARGE($P$137:$P$186,13),$P$137:$P$186,0)),"") -> 0.54562738 | J77: =IFERROR(INDEX($M$137:$M$186,MATCH(LARGE($P$137:$P$186,13),$P$137:$P$186,0)),"") -> 0.31304348 | K77: =IFERROR(INDEX($O$137:$O$186,MATCH(LARGE($P$137:$P$186,13),$P$137:$P$186,0)),"") -> At Risk – Below Pace
B78: 14 | C78: =IFERROR(INDEX($B$137:$B$186,MATCH(LARGE($P$137:$P$186,14),$P$137:$P$186,0)),"") -> Priya Weber | D78: =IFERROR(INDEX($C$137:$C$186,MATCH(LARGE($P$137:$P$186,14),$P$137:$P$186,0)),"") -> Inside Sales | E78: =IFERROR(INDEX($D$137:$D$186,MATCH(LARGE($P$137:$P$186,14),$P$137:$P$186,0)),"") -> NAMER | F78: =IFERROR(INDEX($H$137:$H$186,MATCH(LARGE($P$137:$P$186,14),$P$137:$P$186,0)),"") -> 25900 | G78: =IFERROR(INDEX($I$137:$I$186,MATCH(LARGE($P$137:$P$186,14),$P$137:$P$186,0)),"") -> 48200 | H78: =IFERROR(INDEX($J$137:$J$186,MATCH(LARGE($P$137:$P$186,14),$P$137:$P$186,0)),"") -> 1.8610039 | I78: =IFERROR(INDEX($N$137:$N$186,MATCH(LARGE($P$137:$P$186,14),$P$137:$P$186,0)),"") -> 0.5373444 | J78: =IFERROR(INDEX($M$137:$M$186,MATCH(LARGE($P$137:$P$186,14),$P$137:$P$186,0)),"") -> 0.41964286 | K78: =IFERROR(INDEX($O$137:$O$186,MATCH(LARGE($P$137:$P$186,14),$P$137:$P$186,0)),"") -> At Risk – Below Pace
B79: 15 | C79: =IFERROR(INDEX($B$137:$B$186,MATCH(LARGE($P$137:$P$186,15),$P$137:$P$186,0)),"") -> Sara Duarte | D79: =IFERROR(INDEX($C$137:$C$186,MATCH(LARGE($P$137:$P$186,15),$P$137:$P$186,0)),"") -> Inside Sales | E79: =IFERROR(INDEX($D$137:$D$186,MATCH(LARGE($P$137:$P$186,15),$P$137:$P$186,0)),"") -> APAC | F79: =IFERROR(INDEX($H$137:$H$186,MATCH(LARGE($P$137:$P$186,15),$P$137:$P$186,0)),"") -> 17100 | G79: =IFERROR(INDEX($I$137:$I$186,MATCH(LARGE($P$137:$P$186,15),$P$137:$P$186,0)),"") -> 35300 | H79: =IFERROR(INDEX($J$137:$J$186,MATCH(LARGE($P$137:$P$186,15),$P$137:$P$186,0)),"") -> 2.0643275 | I79: =IFERROR(INDEX($N$137:$N$186,MATCH(LARGE($P$137:$P$186,15),$P$137:$P$186,0)),"") -> 0.48441926 | J79: =IFERROR(INDEX($M$137:$M$186,MATCH(LARGE($P$137:$P$186,15),$P$137:$P$186,0)),"") -> 0.66666667 | K79: =IFERROR(INDEX($O$137:$O$186,MATCH(LARGE($P$137:$P$186,15),$P$137:$P$186,0)),"") -> Watch – Under Target Coverage
B80: 16 | C80: =IFERROR(INDEX($B$137:$B$186,MATCH(LARGE($P$137:$P$186,16),$P$137:$P$186,0)),"") -> Riley Haddad | D80: =IFERROR(INDEX($C$137:$C$186,MATCH(LARGE($P$137:$P$186,16),$P$137:$P$186,0)),"") -> Inside Sales | E80: =IFERROR(INDEX($D$137:$D$186,MATCH(LARGE($P$137:$P$186,16),$P$137:$P$186,0)),"") -> APAC | F80: =IFERROR(INDEX($H$137:$H$186,MATCH(LARGE($P$137:$P$186,16),$P$137:$P$186,0)),"") -> 17100 | G80: =IFERROR(INDEX($I$137:$I$186,MATCH(LARGE($P$137:$P$186,16),$P$137:$P$186,0)),"") -> 39700 | H80: =IFERROR(INDEX($J$137:$J$186,MATCH(LARGE($P$137:$P$186,16),$P$137:$P$186,0)),"") -> 2.3216374 | I80: =IFERROR(INDEX($N$137:$N$186,MATCH(LARGE($P$137:$P$186,16),$P$137:$P$186,0)),"") -> 0.43073048 | J80: =IFERROR(INDEX($M$137:$M$186,MATCH(LARGE($P$137:$P$186,16),$P$137:$P$186,0)),"") -> 0.32653061 | K80: =IFERROR(INDEX($O$137:$O$186,MATCH(LARGE($P$137:$P$186,16),$P$137:$P$186,0)),"") -> At Risk – Below Pace
B81: 17 | C81: =IFERROR(INDEX($B$137:$B$186,MATCH(LARGE($P$137:$P$186,17),$P$137:$P$186,0)),"") -> Morgan Larsen | D81: =IFERROR(INDEX($C$137:$C$186,MATCH(LARGE($P$137:$P$186,17),$P$137:$P$186,0)),"") -> Mid-Market | E81: =IFERROR(INDEX($D$137:$D$186,MATCH(LARGE($P$137:$P$186,17),$P$137:$P$186,0)),"") -> NAMER | F81: =IFERROR(INDEX($H$137:$H$186,MATCH(LARGE($P$137:$P$186,17),$P$137:$P$186,0)),"") -> 28900 | G81: =IFERROR(INDEX($I$137:$I$186,MATCH(LARGE($P$137:$P$186,17),$P$137:$P$186,0)),"") -> 72700 | H81: =IFERROR(INDEX($J$137:$J$186,MATCH(LARGE($P$137:$P$186,17),$P$137:$P$186,0)),"") -> 2.5155709 | I81: =IFERROR(INDEX($N$137:$N$186,MATCH(LARGE($P$137:$P$186,17),$P$137:$P$186,0)),"") -> 0.39752407 | J81: =IFERROR(INDEX($M$137:$M$186,MATCH(LARGE($P$137:$P$186,17),$P$137:$P$186,0)),"") -> 0.28571429 | K81: =IFERROR(INDEX($O$137:$O$186,MATCH(LARGE($P$137:$P$186,17),$P$137:$P$186,0)),"") -> At Risk – Below Pace
B82: 18 | C82: =IFERROR(INDEX($B$137:$B$186,MATCH(LARGE($P$137:$P$186,18),$P$137:$P$186,0)),"") -> Jamie Silva | D82: =IFERROR(INDEX($C$137:$C$186,MATCH(LARGE($P$137:$P$186,18),$P$137:$P$186,0)),"") -> Inside Sales | E82: =IFERROR(INDEX($D$137:$D$186,MATCH(LARGE($P$137:$P$186,18),$P$137:$P$186,0)),"") -> EMEA | F82: =IFERROR(INDEX($H$137:$H$186,MATCH(LARGE($P$137:$P$186,18),$P$137:$P$186,0)),"") -> 15300 | G82: =IFERROR(INDEX($I$137:$I$186,MATCH(LARGE($P$137:$P$186,18),$P$137:$P$186,0)),"") -> 41600 | H82: =IFERROR(INDEX($J$137:$J$186,MATCH(LARGE($P$137:$P$186,18),$P$137:$P$186,0)),"") -> 2.7189542 | I82: =IFERROR(INDEX($N$137:$N$186,MATCH(LARGE($P$137:$P$186,18),$P$137:$P$186,0)),"") -> 0.36778846 | J82: =IFERROR(INDEX($M$137:$M$186,MATCH(LARGE($P$137:$P$186,18),$P$137:$P$186,0)),"") -> 0.37234043 | K82: =IFERROR(INDEX($O$137:$O$186,MATCH(LARGE($P$137:$P$186,18),$P$137:$P$186,0)),"") -> Watch – Under Target Coverage
B83: 19 | C83: =IFERROR(INDEX($B$137:$B$186,MATCH(LARGE($P$137:$P$186,19),$P$137:$P$186,0)),"") -> Liam Muller | D83: =IFERROR(INDEX($C$137:$C$186,MATCH(LARGE($P$137:$P$186,19),$P$137:$P$186,0)),"") -> Inside Sales | E83: =IFERROR(INDEX($D$137:$D$186,MATCH(LARGE($P$137:$P$186,19),$P$137:$P$186,0)),"") -> EMEA | F83: =IFERROR(INDEX($H$137:$H$186,MATCH(LARGE($P$137:$P$186,19),$P$137:$P$186,0)),"") -> 18500 | G83: =IFERROR(INDEX($I$137:$I$186,MATCH(LARGE($P$137:$P$186,19),$P$137:$P$186,0)),"") -> 50800 | H83: =IFERROR(INDEX($J$137:$J$186,MATCH(LARGE($P$137:$P$186,19),$P$137:$P$186,0)),"") -> 2.7459459 | I83: =IFERROR(INDEX($N$137:$N$186,MATCH(LARGE($P$137:$P$186,19),$P$137:$P$186,0)),"") -> 0.36417323 | J83: =IFERROR(INDEX($M$137:$M$186,MATCH(LARGE($P$137:$P$186,19),$P$137:$P$186,0)),"") -> 0.35964912 | K83: =IFERROR(INDEX($O$137:$O$186,MATCH(LARGE($P$137:$P$186,19),$P$137:$P$186,0)),"") -> At Risk – Below Pace
B84: 20 | C84: =IFERROR(INDEX($B$137:$B$186,MATCH(LARGE($P$137:$P$186,20),$P$137:$P$186,0)),"") -> Yuki Dubois | D84: =IFERROR(INDEX($C$137:$C$186,MATCH(LARGE($P$137:$P$186,20),$P$137:$P$186,0)),"") -> Mid-Market | E84: =IFERROR(INDEX($D$137:$D$186,MATCH(LARGE($P$137:$P$186,20),$P$137:$P$186,0)),"") -> LATAM | F84: =IFERROR(INDEX($H$137:$H$186,MATCH(LARGE($P$137:$P$186,20),$P$137:$P$186,0)),"") -> 44000 | G84: =IFERROR(INDEX($I$137:$I$186,MATCH(LARGE($P$137:$P$186,20),$P$137:$P$186,0)),"") -> 129900 | H84: =IFERROR(INDEX($J$137:$J$186,MATCH(LARGE($P$137:$P$186,20),$P$137:$P$186,0)),"") -> 2.9522727 | I84: =IFERROR(INDEX($N$137:$N$186,MATCH(LARGE($P$137:$P$186,20),$P$137:$P$186,0)),"") -> 0.33872209 | J84: =IFERROR(INDEX($M$137:$M$186,MATCH(LARGE($P$137:$P$186,20),$P$137:$P$186,0)),"") -> 0.40350877 | K84: =IFERROR(INDEX($O$137:$O$186,MATCH(LARGE($P$137:$P$186,20),$P$137:$P$186,0)),"") -> Watch – Under Target Coverage
...

Sheet Executive Summary
A1: SALES REP PERFORMANCE EXECUTIVE SUMMARY
A2: ="Performance window: "&D5&" | Reporting month: "&TEXT(A5,"mmm yyyy")&" | Prepared September 1, 2026" -> Performance window: Trailing 12 Months | Reporting month: Aug 2025 | Prepared September 1, 2026
A4: REPORTING MONTH (drop down) | D4: PERFORMANCE WINDOW (drop down) | G4: ATTAINMENT TARGET | I4: STALLED DEAL DAYS | K4: DATA THROUGH
A5: 45870 | D5: Trailing 12 Months | G5: 0.8 | I5: 90 | K5: =TEXT(MAX(Fact_Quota!$B:$B),"mmm yyyy") -> Dec 2025
A7: ="COMPANY PERFORMANCE for: " &D5&"" -> COMPANY PERFORMANCE for: Trailing 12 Months
A9: BOOKINGS WON | D9: QUOTA | G9: ATTAINMENT % | J9: PIPELINE GENERATED
A10: =SUM($G$149:$G$198) -> 10862900 | D10: =SUM($F$149:$F$198) -> 10561500 | G10: =IFERROR(A10/D10,"") -> 1.0285376 | J10: =SUM($I$149:$I$198) -> 36912200
A11: vs. quota, selected window | D11: total quota, selected window | G11: bookings won ÷ quota | J11: new pipeline created
A13: WIN RATE | D13: AVG SALES CYCLE | G13: OPEN PIPELINE $ | J13: ACTIVE REPS
A14: =IFERROR(COUNTIFS(Fact_Pipeline!$J:$J,"Won",Fact_Pipeline!$I:$I,">="&$B$145,Fact_Pipeline!$I:$I,"<="&$B$146)/(COUNTIFS(Fact_Pipeline!$J:$J,"Won",Fact_Pipeline!$I:$I,">="&$B$145,Fact_Pipeline!$I:$I,"<="&$B$146)+COUNTIFS(Fact_Pipeline!$J:$J,"Lost",Fact_Pipeline!$I:$I,">="&$B$145,Fact_Pipeline!$I:$I,"<="&$B$146)),"") -> 0.34735023 | D14: =IFERROR(AVERAGEIFS(Fact_Pipeline!$U:$U,Fact_Pipeline!$J:$J,"Won",Fact_Pipeline!$I:$I,">="&$B$145,Fact_Pipeline!$I:$I,"<="&$B$146),"") -> 24.477612 | G14: =SUMIFS(Fact_Pipeline!$K:$K,Fact_Pipeline!$J:$J,"Open") -> 7275100 | J14: =COUNTIFS(Dim_Reps!$H:$H,"Active") -> 42
A15: won ÷ (won + lost), closed in window | D15: created → closed, won deals | G15: current snapshot, all open deals | J15: current active headcount
A18: RISK FLAGS !! ATTENTION NEEDED
A20: REPS BELOW TARGET | D20: STALLED OPEN DEALS | G20: STALLED PIPELINE $ | J20: LARGEST STALLED DEAL | M20: ="Team and region tables above are color-coded against the attainment target ("&TEXT(G5,"0%")&"): green = at or above target, red = below. See the Watch List for specific reps needing attention." -> Team and region tables above are color-coded against the attainment target (80%): green = at or above target, red = below. See the Watch List for specific reps needing attention.
A21: =COUNTIFS($H$149:$H$198,"<"&G5,$E$149:$E$198,"Active") -> 12 | D21: =COUNTIFS(Fact_Pipeline!$J:$J,"Open",Fact_Pipeline!$D:$D,"<="&($B$146-I5)) -> 0 | G21: =SUMIFS(Fact_Pipeline!$K:$K,Fact_Pipeline!$J:$J,"Open",Fact_Pipeline!$D:$D,"<="&($B$146-I5)) -> 0 | J21: =IFERROR(_xlfn.MAXIFS(Fact_Pipeline!$K:$K,Fact_Pipeline!$J:$J,"Open",Fact_Pipeline!$D:$D,"<="&($B$146-I5)),0) -> 0
A22: active reps below attainment target | D22: open >90 days, no decision | G22: value tied up in stalled deals | J22: single largest at-risk opportunity
A24: Data model: Dim_Reps, Fact_Quota, Fact_Pipeline, Dim_Date, Monthly_Summary (all values USD-normalized). All figures recalculate automatically from the Reporting Month, Performance Window, Attainment Target and Stalled Deal Days controls above. Supporting calculations are on this sheet below row 300 (grouped/collapsed).
A28: ="PERFORMANCE TREND for: " &D5&"" -> PERFORMANCE TREND for: Trailing 12 Months
A68: ="TEAM & REGION PERFORMANCE for: " &D5&"" -> TEAM & REGION PERFORMANCE for: Trailing 12 Months
A88: Team | B88: Active Reps | C88: Quota | D88: Bookings Won | E88: Attainment % | F88: Pipeline Generated | H88: Region | I88: Active Reps | J88: Quota | K88: Bookings Won | L88: Attainment % | M88: Pipeline Generated
A89: Inside Sales | B89: =COUNTIFS(Dim_Reps!$D:$D,A89,Dim_Reps!$H:$H,"Active") -> 21 | C89: =SUMIF($C$149:$C$198,A89,$F$149:$F$198) -> 3745100 | D89: =SUMIF($C$149:$C$198,A89,$G$149:$G$198) -> 3630000 | E89: =IFERROR(D89/C89,"") -> 0.96926651 | F89: =SUMIF($C$149:$C$198,A89,$I$149:$I$198) -> 9558000 | H89: NAMER | I89: =COUNTIFS(Dim_Reps!$E:$E,H89,Dim_Reps!$H:$H,"Active") -> 12 | J89: =SUMIF($D$149:$D$198,H89,$F$149:$F$198) -> 3397000 | K89: =SUMIF($D$149:$D$198,H89,$G$149:$G$198) -> 3378900 | L89: =IFERROR(K89/J89,"") -> 0.99467177 | M89: =SUMIF($D$149:$D$198,H89,$I$149:$I$198) -> 12158300
A90: Mid-Market | B90: =COUNTIFS(Dim_Reps!$D:$D,A90,Dim_Reps!$H:$H,"Active") -> 13 | C90: =SUMIF($C$149:$C$198,A90,$F$149:$F$198) -> 2424200 | D90: =SUMIF($C$149:$C$198,A90,$G$149:$G$198) -> 2656200 | E90: =IFERROR(D90/C90,"") -> 1.0957017 | F90: =SUMIF($C$149:$C$198,A90,$I$149:$I$198) -> 8684700 | H90: EMEA | I90: =COUNTIFS(Dim_Reps!$E:$E,H90,Dim_Reps!$H:$H,"Active") -> 10 | J90: =SUMIF($D$149:$D$198,H90,$F$149:$F$198) -> 2134600 | K90: =SUMIF($D$149:$D$198,H90,$G$149:$G$198) -> 2317600 | L90: =IFERROR(K90/J90,"") -> 1.0857303 | M90: =SUMIF($D$149:$D$198,H90,$I$149:$I$198) -> 7314200
A91: Enterprise | B91: =COUNTIFS(Dim_Reps!$D:$D,A91,Dim_Reps!$H:$H,"Active") -> 5 | C91: =SUMIF($C$149:$C$198,A91,$F$149:$F$198) -> 2027000 | D91: =SUMIF($C$149:$C$198,A91,$G$149:$G$198) -> 2337100 | E91: =IFERROR(D91/C91,"") -> 1.1529847 | F91: =SUMIF($C$149:$C$198,A91,$I$149:$I$198) -> 11389300 | H91: APAC | I91: =COUNTIFS(Dim_Reps!$E:$E,H91,Dim_Reps!$H:$H,"Active") -> 13 | J91: =SUMIF($D$149:$D$198,H91,$F$149:$F$198) -> 2696200 | K91: =SUMIF($D$149:$D$198,H91,$G$149:$G$198) -> 2635600 | L91: =IFERROR(K91/J91,"") -> 0.97752392 | M91: =SUMIF($D$149:$D$198,H91,$I$149:$I$198) -> 9112700
A92: Strategic | B92: =COUNTIFS(Dim_Reps!$D:$D,A92,Dim_Reps!$H:$H,"Active") -> 3 | C92: =SUMIF($C$149:$C$198,A92,$F$149:$F$198) -> 2365200 | D92: =SUMIF($C$149:$C$198,A92,$G$149:$G$198) -> 2239600 | E92: =IFERROR(D92/C92,"") -> 0.94689667 | F92: =SUMIF($C$149:$C$198,A92,$I$149:$I$198) -> 7280200 | H92: LATAM | I92: =COUNTIFS(Dim_Reps!$E:$E,H92,Dim_Reps!$H:$H,"Active") -> 7 | J92: =SUMIF($D$149:$D$198,H92,$F$149:$F$198) -> 2333700 | K92: =SUMIF($D$149:$D$198,H92,$G$149:$G$198) -> 2530800 | L92: =IFERROR(K92/J92,"") -> 1.0844582 | M92: =SUMIF($D$149:$D$198,H92,$I$149:$I$198) -> 8327000
A95: ="ACTIVE REP LEADERBOARD for: " &D5&"" -> ACTIVE REP LEADERBOARD for: Trailing 12 Months
A97: TOP 5 PERFORMERS | H97: REPS NEEDING ATTENTION (LOWEST ATTAINMENT)
A98: Rank | B98: Rep Name | C98: Team | D98: Region | E98: Attainment % | F98: Bookings Won | H98: Rank | I98: Rep Name | J98: Team | K98: Region | L98: Attainment % | M98: Bookings Won
A99: 1 | B99: =IFERROR(INDEX($B$149:$B$198,MATCH(LARGE($J$149:$J$198,1),$J$149:$J$198,0)),"") -> Erik Duarte | C99: =IFERROR(INDEX($C$149:$C$198,MATCH(LARGE($J$149:$J$198,1),$J$149:$J$198,0)),"") -> Mid-Market | D99: =IFERROR(INDEX($D$149:$D$198,MATCH(LARGE($J$149:$J$198,1),$J$149:$J$198,0)),"") -> EMEA | E99: =IFERROR(INDEX($H$149:$H$198,MATCH(LARGE($J$149:$J$198,1),$J$149:$J$198,0)),"") -> 1.5079606 | F99: =IFERROR(INDEX($G$149:$G$198,MATCH(LARGE($J$149:$J$198,1),$J$149:$J$198,0)),"") -> 397800 | H99: 1 | I99: =IFERROR(INDEX($B$149:$B$198,MATCH(SMALL($J$149:$J$198,1),$J$149:$J$198,0)),"") -> Karim Rivera | J99: =IFERROR(INDEX($C$149:$C$198,MATCH(SMALL($J$149:$J$198,1),$J$149:$J$198,0)),"") -> Mid-Market | K99: =IFERROR(INDEX($D$149:$D$198,MATCH(SMALL($J$149:$J$198,1),$J$149:$J$198,0)),"") -> APAC | L99: =IFERROR(INDEX($H$149:$H$198,MATCH(SMALL($J$149:$J$198,1),$J$149:$J$198,0)),"") -> 0 | M99: =IFERROR(INDEX($G$149:$G$198,MATCH(SMALL($J$149:$J$198,1),$J$149:$J$198,0)),"") -> 0
A100: 2 | B100: =IFERROR(INDEX($B$149:$B$198,MATCH(LARGE($J$149:$J$198,2),$J$149:$J$198,0)),"") -> Yuki Dubois | C100: =IFERROR(INDEX($C$149:$C$198,MATCH(LARGE($J$149:$J$198,2),$J$149:$J$198,0)),"") -> Mid-Market | D100: =IFERROR(INDEX($D$149:$D$198,MATCH(LARGE($J$149:$J$198,2),$J$149:$J$198,0)),"") -> LATAM | E100: =IFERROR(INDEX($H$149:$H$198,MATCH(LARGE($J$149:$J$198,2),$J$149:$J$198,0)),"") -> 1.3646346 | F100: =IFERROR(INDEX($G$149:$G$198,MATCH(LARGE($J$149:$J$198,2),$J$149:$J$198,0)),"") -> 360400 | H100: 2 | I100: =IFERROR(INDEX($B$149:$B$198,MATCH(SMALL($J$149:$J$198,2),$J$149:$J$198,0)),"") -> Erik Kim | J100: =IFERROR(INDEX($C$149:$C$198,MATCH(SMALL($J$149:$J$198,2),$J$149:$J$198,0)),"") -> Mid-Market | K100: =IFERROR(INDEX($D$149:$D$198,MATCH(SMALL($J$149:$J$198,2),$J$149:$J$198,0)),"") -> NAMER | L100: =IFERROR(INDEX($H$149:$H$198,MATCH(SMALL($J$149:$J$198,2),$J$149:$J$198,0)),"") -> 0 | M100: =IFERROR(INDEX($G$149:$G$198,MATCH(SMALL($J$149:$J$198,2),$J$149:$J$198,0)),"") -> 0
A101: 3 | B101: =IFERROR(INDEX($B$149:$B$198,MATCH(LARGE($J$149:$J$198,3),$J$149:$J$198,0)),"") -> Felix Okafor | C101: =IFERROR(INDEX($C$149:$C$198,MATCH(LARGE($J$149:$J$198,3),$J$149:$J$198,0)),"") -> Mid-Market | D101: =IFERROR(INDEX($D$149:$D$198,MATCH(LARGE($J$149:$J$198,3),$J$149:$J$198,0)),"") -> EMEA | E101: =IFERROR(INDEX($H$149:$H$198,MATCH(LARGE($J$149:$J$198,3),$J$149:$J$198,0)),"") -> 1.3458618 | F101: =IFERROR(INDEX($G$149:$G$198,MATCH(LARGE($J$149:$J$198,3),$J$149:$J$198,0)),"") -> 354500 | H101: 3 | I101: =IFERROR(INDEX($B$149:$B$198,MATCH(SMALL($J$149:$J$198,3),$J$149:$J$198,0)),"") -> Lucas Cohen | J101: =IFERROR(INDEX($C$149:$C$198,MATCH(SMALL($J$149:$J$198,3),$J$149:$J$198,0)),"") -> Enterprise | K101: =IFERROR(INDEX($D$149:$D$198,MATCH(SMALL($J$149:$J$198,3),$J$149:$J$198,0)),"") -> NAMER | L101: =IFERROR(INDEX($H$149:$H$198,MATCH(SMALL($J$149:$J$198,3),$J$149:$J$198,0)),"") -> 0.19677996 | M101: =IFERROR(INDEX($G$149:$G$198,MATCH(SMALL($J$149:$J$198,3),$J$149:$J$198,0)),"") -> 22000
A102: 4 | B102: =IFERROR(INDEX($B$149:$B$198,MATCH(LARGE($J$149:$J$198,4),$J$149:$J$198,0)),"") -> Lucas Okafor | C102: =IFERROR(INDEX($C$149:$C$198,MATCH(LARGE($J$149:$J$198,4),$J$149:$J$198,0)),"") -> Inside Sales | D102: =IFERROR(INDEX($D$149:$D$198,MATCH(LARGE($J$149:$J$198,4),$J$149:$J$198,0)),"") -> APAC | E102: =IFERROR(INDEX($H$149:$H$198,MATCH(LARGE($J$149:$J$198,4),$J$149:$J$198,0)),"") -> 1.2811657 | F102: =IFERROR(INDEX($G$149:$G$198,MATCH(LARGE($J$149:$J$198,4),$J$149:$J$198,0)),"") -> 237400 | H102: 4 | I102: =IFERROR(INDEX($B$149:$B$198,MATCH(SMALL($J$149:$J$198,4),$J$149:$J$198,0)),"") -> Rafael Weber | J102: =IFERROR(INDEX($C$149:$C$198,MATCH(SMALL($J$149:$J$198,4),$J$149:$J$198,0)),"") -> Mid-Market | K102: =IFERROR(INDEX($D$149:$D$198,MATCH(SMALL($J$149:$J$198,4),$J$149:$J$198,0)),"") -> APAC | L102: =IFERROR(INDEX($H$149:$H$198,MATCH(SMALL($J$149:$J$198,4),$J$149:$J$198,0)),"") -> 0.35578145 | M102: =IFERROR(INDEX($G$149:$G$198,MATCH(SMALL($J$149:$J$198,4),$J$149:$J$198,0)),"") -> 28000
A103: 5 | B103: =IFERROR(INDEX($B$149:$B$198,MATCH(LARGE($J$149:$J$198,5),$J$149:$J$198,0)),"") -> Lucas Duarte | C103: =IFERROR(INDEX($C$149:$C$198,MATCH(LARGE($J$149:$J$198,5),$J$149:$J$198,0)),"") -> Inside Sales | D103: =IFERROR(INDEX($D$149:$D$198,MATCH(LARGE($J$149:$J$198,5),$J$149:$J$198,0)),"") -> LATAM | E103: =IFERROR(INDEX($H$149:$H$198,MATCH(LARGE($J$149:$J$198,5),$J$149:$J$198,0)),"") -> 1.2717976 | F103: =IFERROR(INDEX($G$149:$G$198,MATCH(LARGE($J$149:$J$198,5),$J$149:$J$198,0)),"") -> 236300 | H103: 5 | I103: =IFERROR(INDEX($B$149:$B$198,MATCH(SMALL($J$149:$J$198,5),$J$149:$J$198,0)),"") -> Sara Duarte | J103: =IFERROR(INDEX($C$149:$C$198,MATCH(SMALL($J$149:$J$198,5),$J$149:$J$198,0)),"") -> Inside Sales | K103: =IFERROR(INDEX($D$149:$D$198,MATCH(SMALL($J$149:$J$198,5),$J$149:$J$198,0)),"") -> APAC | L103: =IFERROR(INDEX($H$149:$H$198,MATCH(SMALL($J$149:$J$198,5),$J$149:$J$198,0)),"") -> 0.52252252 | M103: =IFERROR(INDEX($G$149:$G$198,MATCH(SMALL($J$149:$J$198,5),$J$149:$J$198,0)),"") -> 5800
A106: ="PIPELINE & FUNNEL HEALTH for: " &D5&"" -> PIPELINE & FUNNEL HEALTH for: Trailing 12 Months
A125: Stage | B125: Count | C125: % of Created | E125: Source | F125: Won | G125: Lost | H125: Win Rate | I125: Won $ Value | K125: Lost Reason | L125: Count | M125: $ Value | N125: % of Total Lost
A126: Created | B126: =COUNTIFS(Fact_Pipeline!$D:$D,">="&$B$145,Fact_Pipeline!$D:$D,"<="&$B$146) -> 3560 | C126: =IFERROR(B126/$B$126,"") -> 1 | E126: Outbound Prospecting | F126: =COUNTIFS(Fact_Pipeline!$C:$C,E126,Fact_Pipeline!$J:$J,"Won",Fact_Pipeline!$I:$I,">="&$B$145,Fact_Pipeline!$I:$I,"<="&$B$146) -> 487 | G126: =COUNTIFS(Fact_Pipeline!$C:$C,E126,Fact_Pipeline!$J:$J,"Lost",Fact_Pipeline!$I:$I,">="&$B$145,Fact_Pipeline!$I:$I,"<="&$B$146) -> 913 | H126: =IFERROR(F126/(F126+G126),"") -> 0.34785714 | I126: =SUMIFS(Fact_Pipeline!$K:$K,Fact_Pipeline!$C:$C,E126,Fact_Pipeline!$J:$J,"Won",Fact_Pipeline!$I:$I,">="&$B$145,Fact_Pipeline!$I:$I,"<="&$B$146) -> 3906200 | K126: Budget | L126: =COUNTIFS(Fact_Pipeline!$L:$L,K126,Fact_Pipeline!$I:$I,">="&$B$145,Fact_Pipeline!$I:$I,"<="&$B$146) -> 667 | M126: =SUMIFS(Fact_Pipeline!$K:$K,Fact_Pipeline!$L:$L,K126,Fact_Pipeline!$I:$I,">="&$B$145,Fact_Pipeline!$I:$I,"<="&$B$146) -> 6633000 | N126: =IFERROR(L126/SUM($L$126:$L$130),"") -> 0.29435128
A127: Reached Qualified | B127: =COUNTIFS(Fact_Pipeline!$D:$D,">="&$B$145,Fact_Pipeline!$D:$D,"<="&$B$146,Fact_Pipeline!$E:$E,"<>") -> 3560 | C127: =IFERROR(B127/$B$126,"") -> 1 | E127: Inbound Marketing | F127: =COUNTIFS(Fact_Pipeline!$C:$C,E127,Fact_Pipeline!$J:$J,"Won",Fact_Pipeline!$I:$I,">="&$B$145,Fact_Pipeline!$I:$I,"<="&$B$146) -> 302 | G127: =COUNTIFS(Fact_Pipeline!$C:$C,E127,Fact_Pipeline!$J:$J,"Lost",Fact_Pipeline!$I:$I,">="&$B$145,Fact_Pipeline!$I:$I,"<="&$B$146) -> 590 | H127: =IFERROR(F127/(F127+G127),"") -> 0.33856502 | I127: =SUMIFS(Fact_Pipeline!$K:$K,Fact_Pipeline!$C:$C,E127,Fact_Pipeline!$J:$J,"Won",Fact_Pipeline!$I:$I,">="&$B$145,Fact_Pipeline!$I:$I,"<="&$B$146) -> 2824300 | K127: Lost to Competitor | L127: =COUNTIFS(Fact_Pipeline!$L:$L,K127,Fact_Pipeline!$I:$I,">="&$B$145,Fact_Pipeline!$I:$I,"<="&$B$146) -> 634 | M127: =SUMIFS(Fact_Pipeline!$K:$K,Fact_Pipeline!$L:$L,K127,Fact_Pipeline!$I:$I,">="&$B$145,Fact_Pipeline!$I:$I,"<="&$B$146) -> 7177800 | N127: =IFERROR(L127/SUM($L$126:$L$130),"") -> 0.27978817
A128: Reached Meeting | B128: =COUNTIFS(Fact_Pipeline!$D:$D,">="&$B$145,Fact_Pipeline!$D:$D,"<="&$B$146,Fact_Pipeline!$F:$F,"<>") -> 3199 | C128: =IFERROR(B128/$B$126,"") -> 0.89859551 | E128: Referral | F128: =COUNTIFS(Fact_Pipeline!$C:$C,E128,Fact_Pipeline!$J:$J,"Won",Fact_Pipeline!$I:$I,">="&$B$145,Fact_Pipeline!$I:$I,"<="&$B$146) -> 171 | G128: =COUNTIFS(Fact_Pipeline!$C:$C,E128,Fact_Pipeline!$J:$J,"Lost",Fact_Pipeline!$I:$I,">="&$B$145,Fact_Pipeline!$I:$I,"<="&$B$146) -> 311 | H128: =IFERROR(F128/(F128+G128),"") -> 0.35477178 | I128: =SUMIFS(Fact_Pipeline!$K:$K,Fact_Pipeline!$C:$C,E128,Fact_Pipeline!$J:$J,"Won",Fact_Pipeline!$I:$I,">="&$B$145,Fact_Pipeline!$I:$I,"<="&$B$146) -> 1483400 | K128: No Decision / Timing | L128: =COUNTIFS(Fact_Pipeline!$L:$L,K128,Fact_Pipeline!$I:$I,">="&$B$145,Fact_Pipeline!$I:$I,"<="&$B$146) -> 460 | M128: =SUMIFS(Fact_Pipeline!$K:$K,Fact_Pipeline!$L:$L,K128,Fact_Pipeline!$I:$I,">="&$B$145,Fact_Pipeline!$I:$I,"<="&$B$146) -> 4914400 | N128: =IFERROR(L128/SUM($L$126:$L$130),"") -> 0.20300088
